#include <exception>

int main() {
  try {

  } catch (const std::exception &e) {
    // ...
  }
}
