void f() {}

try {
  f();
}
catch (const std::exception& e) {
  // ...
}